Workbook

Sheet Sheet1
A1: ('T265', 'Time (sec)') | B1: ('T265', 'X (m)') | C1: ('T265', 'Y (m)') | D1: ('T265', 'Z (m)') | E1: ('T265', 'Row (rad)') | F1: ('T265', 'Pitch (rad)') | G1: ('T265', 'Yaw (rad)') | H1: ('T265', 'Yaw (deg)') | I1: ('Turtlebot', 'Time (sec)') | J1: ('Turtlebot', 'X (m)') | K1: ('Turtlebot', 'Y (m)') | L1: ('Turtlebot', 'Z (m)') | M1: ('Turtlebot', 'Row (rad)') | N1: ('Turtlebot', 'Pitch (rad)') | O1: ('Turtlebot', 'Yaw (rad)') | P1: ('Turtlebot', 'Yaw (deg)') | Q1: ('Estimate', 'Time (sec)') | R1: ('Estimate', 'X (m)') | S1: ('Estimate', 'Y (m)') | T1: ('Estimate', 'Z (m)') | U1: ('Estimate', 'Row (rad)') | V1: ('Estimate', 'Pitch (rad)') | W1: ('Estimate', 'Yaw (rad)') | X1: ('Estimate', 'Yaw (deg)')
A2: 0 | B2: 0 | C2: 0 | D2: 0 | E2: 0 | F2: 0 | G2: 0 | H2: 0 | I2: 0 | J2: 0 | K2: 0 | L2: 0 | M2: 0 | N2: 0 | O2: 0 | P2: 0 | Q2: 0 | R2: 0 | S2: 0 | T2: 0 | U2: 0 | V2: 0 | W2: 0 | X2: 0
A3: -0.008574009 | B3: -0.0010200279 | C3: 0.00091544539 | D3: -0.0014444962 | E3: 0.012985554 | F3: 0.044131987 | G3: -0.00037275799 | H3: 359.97864 | I3: -0.007024332 | J3: 0 | K3: 0 | L3: 0 | M3: 0 | N3: 0 | O3: 0 | P3: 0 | Q3: -1.6007198e+09 | R3: 0 | S3: 0 | T3: 0 | U3: 0 | V3: 0 | W3: 0 | X3: 0
A4: 0.086407185 | B4: -0.0014565727 | C4: 0.00073432457 | D4: -0.0010956323 | E4: 0.012669625 | F4: 0.04113395 | G4: -0.00040864564 | H4: 359.97659 | I4: 0.072962251 | J4: 0 | K4: 0 | L4: 0 | M4: 0 | N4: 0 | O4: 0 | P4: 0 | Q4: -1.6007198e+09 | R4: 0 | S4: 0 | T4: 0 | U4: 0 | V4: 0 | W4: 0 | X4: 0
A5: 0.17636871 | B5: -0.0012462448 | C5: 0.00058772898 | D5: -0.00099460711 | E5: 0.011230174 | F5: 0.046039037 | G5: -0.00065089647 | H5: 359.96271 | I5: 0.15286887 | J5: 0 | K5: 0 | L5: 0 | M5: 0 | N5: 0 | O5: 0 | P5: 0 | Q5: -1.6007198e+09 | R5: 0 | S5: 0 | T5: 0 | U5: 0 | V5: 0 | W5: 0 | X5: 0
A6: 0.2813468 | B6: 0.0001792368 | C6: 0.0001901661 | D6: -0.00082317617 | E6: 0.011714632 | F6: 0.05003845 | G6: -0.00052916878 | H6: 359.96968 | I6: 0.29075378 | J6: 0 | K6: 0 | L6: 0 | M6: 0 | N6: 0 | O6: 0 | P6: 0 | Q6: -1.6007198e+09 | R6: 0 | S6: 0 | T6: 0 | U6: 0 | V6: 0 | W6: 0 | X6: 0
A7: 0.41132069 | B7: 0.00044789945 | C7: -0.00028990791 | D7: -0.00048396696 | E7: 0.01091119 | F7: 0.048923591 | G7: -0.00054222912 | H7: 359.96893 | I7: 0.39265553 | J7: 0 | K7: 0 | L7: 0 | M7: 0 | N7: 0 | O7: 0 | P7: 0 | Q7: 0.39775181 | U7: 0 | V7: 0 | W7: 0 | X7: 0
A8: 0.50130272 | B8: -0.00043560233 | C8: 0.0006920576 | D8: -0.00087610976 | E8: 0.00916641 | F8: 0.047359735 | G8: -0.00048344875 | H8: 359.9723 | I8: 0.47267141 | J8: 0 | K8: 0 | L8: 0 | M8: 0 | N8: 0 | O8: 0 | P8: 0 | Q8: 0.49245787 | R8: 0.0043763714 | S8: -0.0032643584 | T8: -0.0010063679 | U8: 0.0069218922 | V8: 0.00060897674 | W8: 0.0085473657 | X8: 0.48972798
A9: 0.59128475 | B9: -0.00048079295 | C9: 0.00034700209 | D9: -0.00084376172 | E9: 0.0098520122 | F9: 0.04749397 | G9: -0.00041292308 | H9: 359.97634 | I9: 0.55262864 | J9: 0 | K9: 0 | L9: 0 | M9: 0 | N9: 0 | O9: 0 | P9: 0 | Q9: 0.57794786 | R9: 0.0042736421 | S9: -0.0031541593 | T9: -0.0010912128 | U9: 0.0068107188 | V9: 0.00068119564 | W9: 0.0085995755 | X9: 0.49271938
A10: 0.6862433 | B10: -0.00053842843 | C10: 0.00051428855 | D10: -0.00071853324 | E10: 0.0094673635 | F10: 0.047628942 | G10: -0.00046497843 | H10: 359.97336 | I10: 0.63247436 | J10: 0 | K10: 0 | L10: 0 | M10: 0 | N10: 0 | O10: 0 | P10: 0 | Q10: 0.66052699 | R10: 0.0043568145 | S10: -0.0031882457 | T10: -0.0010660557 | U10: 0.0068671162 | V10: 0.00069297986 | W10: 0.0086016798 | X10: 0.49283995
A11: 0.78622341 | B11: 0.00029928534 | C11: 0.00015729791 | D11: -0.00042787922 | E11: 0.0097341426 | F11: 0.048281707 | G11: -0.00038698484 | H11: 359.97783 | I11: 0.79250431 | J11: 0 | K11: 0 | L11: 0 | M11: 0 | N11: 0 | O11: 0 | P11: 0 | Q11: 0.81179285 | R11: 0.0040867227 | S11: -0.0032967619 | T11: -0.00074551559 | U11: 0.006998102 | V11: 0.00078066144 | W11: 0.0086675027 | X11: 0.49661133
A12: 0.88120437 | B12: -9.998148e-05 | C12: 6.2518913e-05 | D12: -0.00066754984 | E12: 0.0098185651 | F12: 0.047888857 | G12: -0.00047342663 | H12: 359.97287 | I12: 0.872358 | J12: 0 | K12: 0 | L12: 0 | M12: 0 | N12: 0 | O12: 0 | P12: 0 | Q12: 0.87708878 | R12: 0.0040144044 | S12: -0.0033414865 | T12: -0.00089927471 | U12: 0.0069700061 | V12: 0.00069184937 | W12: 0.0086620105 | X12: 0.49629664
A13: 0.97118616 | B13: -0.00066497334 | C13: 0.00045139596 | D13: -0.00059998571 | E13: 0.0095202943 | F13: 0.047673375 | G13: -0.00038110562 | H13: 359.97816 | I13: 0.95228704 | J13: 0 | K13: 0 | L13: 0 | M13: 0 | N13: 0 | O13: 0 | P13: 0 | Q13: 0.96310878 | R13: 0.0036923242 | S13: -0.0033835322 | T13: -0.00089524613 | U13: 0.0068843954 | V13: 0.00065067176 | W13: 0.0086233666 | X13: 0.49408251
A14: 1.1111584 | B14: -0.00033561949 | C14: 0.00025441116 | D14: -0.00062989153 | E14: 0.0096225262 | F14: 0.047843267 | G14: -0.00040204557 | H14: 359.97696 | I14: 1.090152 | J14: 0 | K14: 0 | L14: 0 | M14: 0 | N14: 0 | O14: 0 | P14: 0 | Q14: 1.1082318 | R14: 0.0037549736 | S14: -0.0033971274 | T14: -0.00078634438 | U14: 0.0069637199 | V14: 0.00067685928 | W14: 0.0086423361 | X14: 0.49516938
A15: 1.2011466 | B15: -0.00037013419 | C15: 0.00034429162 | D15: -0.00051582523 | E15: 0.0094984586 | F15: 0.047852069 | G15: -0.00050373552 | H15: 359.97114 | I15: 1.1931878 | J15: 0 | K15: 0 | L15: 0 | M15: 0 | N15: 0 | O15: 0 | P15: 0 | Q15: 1.1621649 | R15: 0.0036150879 | S15: -0.0033154247 | T15: -0.0007427936 | U15: 0.0069427831 | V15: 0.00067636967 | W15: 0.0086219043 | X15: 0.49399873
A16: 1.2911286 | B16: -0.00034649562 | C16: 0.00035606383 | D16: -0.00067836663 | E16: 0.0093708263 | F16: 0.047862509 | G16: -0.00044807534 | H16: 359.97433 | I16: 1.2722169 | J16: 0 | K16: 0 | L16: 0 | M16: 0 | N16: 0 | O16: 0 | P16: 0 | Q16: 1.2692578 | R16: 0.0037124729 | S16: -0.003358256 | T16: -0.00060004246 | U16: 0.0069475187 | V16: 0.00074634982 | W16: 0.0086444677 | X16: 0.49529151
A17: 1.3811107 | B17: -0.00045245606 | C17: 0.00023477584 | D17: -0.00033821253 | E17: 0.0093928546 | F17: 0.04768755 | G17: -0.00040820716 | H17: 359.97661 | I17: 1.4100127 | J17: 0 | K17: 0 | L17: 0 | M17: 0 | N17: 0 | O17: 0 | P17: 0 | Q17: 1.3825569 | R17: 0.0036210181 | S17: -0.003307638 | T17: -0.00075582812 | U17: 0.0068546526 | V17: 0.00070491683 | W17: 0.008686675 | X17: 0.49770981
A18: 1.4810908 | B18: -0.00037497995 | C18: 0.00018438655 | D18: -0.00071130326 | E18: 0.0093696326 | F18: 0.047818263 | G18: -0.00042297007 | H18: 359.97577 | I18: 1.4909199 | J18: 0 | K18: 0 | L18: 0 | M18: 0 | N18: 0 | O18: 0 | P18: 0 | Q18: 1.4924419 | R18: 0.003732188 | S18: -0.0032622483 | T18: -0.00070826969 | U18: 0.0068843221 | V18: 0.00074736178 | W18: 0.0086735741 | X18: 0.49695919
A19: 1.6160636 | B19: -9.0592468e-05 | C19: 0.00034505854 | D19: -0.00090379402 | E19: 0.0092018238 | F19: 0.047747237 | G19: -0.00035300063 | H19: 359.97977 | I19: 1.5929347 | J19: 0 | K19: 0 | L19: 0 | M19: 0 | N19: 0 | O19: 0 | P19: 0 | Q19: 1.6027858 | R19: 0.0037527727 | S19: -0.0033489288 | T19: -0.00080834707 | U19: 0.0068991613 | V19: 0.00064973609 | W19: 0.0086536195 | X19: 0.49581588
... A80: 7.6947091 | B80: 0.49651504 | C80: -7.3636642e-05 | D80: -0.0060133808 | E80: 0.0096456313 | F80: 0.035597862 | G80: 0.0014066568 | H80: 0.080595498 | I80: 7.7087749 | J80: 0.5062508 | K80: -0.00014936142 | L80: 0 | M80: 0 | N80: 0 | O80: 0.0010471976 | P80: 0.06 | Q80: 7.5869348 | R80: 0.42869771 | S80: 0.011463052 | T80: 0.0067722304 | U80: 0.039453418 | V80: 0.0026917838 | W80: 0.035336812 | X80: 2.0246502
A81: 7.7846913 | B81: 0.5116899 | C81: -0.00047851237 | D81: -0.010463135 | E81: 0.0095483608 | F81: 0.048004079 | G81: 0.001013955 | H81: 0.058095341 | I81: 7.768575 | J81: 0.51034482 | K81: -0.00014507417 | L81: 0 | M81: 0 | N81: 0 | O81: 0.0010471976 | P81: 0.06 | Q81: 7.8055458 | U81: 0 | V81: 0 | W81: 0 | X81: 0
A82: 7.8746736 | B82: 0.51549232 | C82: 0.00067708315 | D82: -0.010961742 | E82: 0.0082137386 | F82: 0.056656316 | G82: 0.0012535844 | H82: 0.071825094 | I82: 7.8884875 | J82: 0.51128303 | K82: -0.0001445606 | L82: 0 | M82: 0 | N82: 0 | O82: 0.00034906585 | P82: 0.02 | Q82: 7.8679368 | R82: 0.49407219 | S82: -0.0024746312 | T82: -0.0042033421 | U82: 0.024362869 | V82: 0.003251203 | W82: 0.046337626 | X82: 2.6549504
A83: 8.0096474 | B83: 0.50403214 | C83: -0.0001205083 | D83: -0.0056837816 | E83: 0.010085546 | F83: 0.028927319 | G83: 0.00055272192 | H83: 0.031668633 | I83: 7.9484667 | J83: 0.51158156 | K83: -0.00014445639 | L83: 0 | M83: 0 | N83: 0 | O83: 0.00017453293 | P83: 0.01 | Q83: 7.8679368 | R83: 0.49407219 | S83: -0.0024746312 | T83: -0.0042033421 | U83: 0.024362869 | V83: 0.003251203 | W83: 0.046337626 | X83: 2.6549504
A84: 8.0996294 | B84: 0.50546044 | C84: 0.00047555144 | D84: -0.0089708641 | E84: 0.010223174 | F84: 0.033608076 | G84: 0.00041729493 | H84: 0.023909238 | I84: 8.0883467 | J84: 0.51064334 | K84: -0.00014426287 | L84: 0 | M84: 0 | N84: 0 | O84: -0.0006981317 | P84: 359.96 | Q84: 8.0918629 | R84: 0.48020267 | S84: -0.0014594326 | T84: 0.0018792815 | U84: 0.055935867 | V84: 0.0025819587 | W84: 0.0530774 | X84: 3.041111
A85: 8.1895626 | B85: 0.50694638 | C85: 0.00025912479 | D85: -0.0091872616 | E85: 0.0096102901 | F85: 0.037993029 | G85: 0.00098184754 | H85: 0.05625572 | I85: 8.1683258 | J85: 0.51081393 | K85: -0.00014438196 | L85: 0 | M85: 0 | N85: 0 | O85: -0.0006981317 | P85: 359.96 | Q85: 8.192956 | R85: 0.48368983 | S85: -0.0010076664 | T85: -6.3296154e-05 | U85: 0.049706848 | V85: 0.0035567273 | W85: 0.05353941 | X85: 3.0675822
A86: 8.2795446 | B86: 0.50568461 | C86: 0.00022012882 | D86: -0.0080768978 | E86: 0.0099116628 | F86: 0.034669891 | G86: 0.0008980264 | H86: 0.051453122 | I86: 8.2881947 | J86: 0.51111245 | K86: -0.00014459037 | L86: 0 | M86: 0 | N86: 0 | O86: -0.00017453293 | P86: 359.99 | Q86: 8.3003328 | R86: 0.48685946 | S86: -0.0023371609 | T86: -0.0039579759 | U86: 0.050906762 | V86: 0.0029601012 | W86: 0.054016164 | X86: 3.0948982
A87: 8.4145188 | B87: 0.50587302 | C87: -0.0002814891 | D87: -0.0072222352 | E87: 0.0097936045 | F87: 0.036456854 | G87: 0.0014078482 | H87: 0.080663758 | I87: 8.4082348 | J87: 0.51111245 | K87: -0.00014459037 | L87: 0 | M87: 0 | N87: 0 | O87: -0.00017453293 | P87: 359.99 | Q87: 8.3878598 | R87: 0.4817475 | S87: 8.2669621e-05 | T87: -0.0015000395 | U87: 0.052398013 | V87: 0.0030557187 | W87: 0.053188696 | X87: 3.0474878
A88: 8.5094998 | B88: 0.50563979 | C88: -1.523895e-05 | D88: -0.0080892742 | E88: 0.0098430291 | F88: 0.034800286 | G88: 0.0012980084 | H88: 0.074370401 | I88: 8.4890916 | J88: 0.51111245 | K88: -0.00014459037 | L88: 0 | M88: 0 | N88: 0 | O88: 0.00017453293 | P88: 0.01 | Q88: 8.488555 | R88: 0.48800227 | S88: -0.0022566093 | T88: -0.0054250466 | U88: 0.050407106 | V88: 0.0027577751 | W88: 0.05393803 | X88: 3.0904215
A89: 8.5944839 | B89: 0.50521898 | C89: 0.00033622154 | D89: -0.0071841832 | E89: 0.0097793366 | F89: 0.035337258 | G89: 0.00096638267 | H89: 0.055369648 | I89: 8.5859024 | J89: 0.51111245 | K89: -0.00014459037 | L89: 0 | M89: 0 | N89: 0 | O89: 0.00017453293 | P89: 0.01 | Q89: 8.575866 | R89: 0.48350709 | S89: -2.8414508e-05 | T89: -0.0028327794 | U89: 0.051878542 | V89: 0.0028442293 | W89: 0.05356589 | X89: 3.0690994
A90: 8.6844513 | B90: 0.50574046 | C90: 0.00033542432 | D90: -0.0079239011 | E90: 0.0097738487 | F90: 0.035334191 | G90: 0.001065346 | H90: 0.061039829 | I90: 8.6678383 | J90: 0.51111245 | K90: -0.00014459037 | L90: 0 | M90: 0 | N90: 0 | O90: 0.00034906585 | P90: 0.02 | Q90: 8.7110598 | R90: 0.48561716 | S90: -0.00083466255 | T90: -0.0046529457 | U90: 0.050369829 | V90: 0.0029285172 | W90: 0.053789772 | X90: 3.0819269
A91: 8.7894313 | B91: 0.50550723 | C91: 0.00071945757 | D91: -0.0075070616 | E91: 0.0098777821 | F91: 0.035088129 | G91: 0.001025559 | H91: 0.058760201 | I91: 8.7858146 | J91: 0.51111245 | K91: -0.00014459037 | L91: 0 | M91: 0 | N91: 0 | O91: 0.0006981317 | P91: 0.04 | Q91: 8.7892179 | R91: 0.4853102 | S91: -0.00070278494 | T91: -0.0038751123 | U91: 0.051544466 | V91: 0.0028866528 | W91: 0.053721776 | X91: 3.078031
A92: 8.9194052 | B92: 0.50593781 | C92: 0.0017221788 | D92: -0.008460667 | E92: 0.0093256049 | F92: 0.033950849 | G92: 0.0058816942 | H92: 0.33699626 | I92: 8.8677453 | J92: 0.5111551 | K92: -0.0001445606 | L92: 0 | M92: 0 | N92: 0 | O92: 0.0006981317 | P92: 0.04 | Q92: 8.8897228 | R92: 0.48550991 | S92: -0.0009651881 | T92: -0.0052490148 | U92: 0.050415591 | V92: 0.0026259923 | W92: 0.053913547 | X92: 3.0890187
A93: 9.0093884 | B93: 0.50570738 | C93: 0.0027907344 | D93: -0.0079296492 | E93: 0.0088198231 | F93: 0.034754407 | G93: 0.014775966 | H93: 0.84660051 | I93: 9.0056186 | J93: 0.51158156 | K93: -0.00014425543 | L93: 0 | M93: 0 | N93: 0 | O93: 0.0083775804 | P93: 0.48 | Q93: 9.0051489 | R93: 0.48100691 | S93: 0.0020276417 | T93: -0.005207362 | U93: 0.051168335 | V93: 0.0026843334 | W93: 0.058047453 | X93: 3.3258741
... A170: 16.682683 | B170: 0.39807057 | C170: 0.2195231 | D170: -0.0057919193 | E170: 0.007567795 | F170: 0.015397978 | G170: 1.5571773 | H170: 89.219689 | I170: 16.68333 | J170: 0.5166299 | K170: 0.12851768 | L170: 0 | M170: 0 | N170: 0 | O170: 1.5465363 | P170: 88.61 | Q170: 16.59881 | R170: 0.54357999 | S170: 0.028427616 | T170: -0.0098505369 | U170: 0.11963486 | V170: -0.019564843 | W170: 1.5417384 | X170: 88.335105
A171: 16.772666 | B171: 0.39797261 | C171: 0.23266289 | D171: -0.0047057746 | E171: 0.0076589285 | F171: 0.015643189 | G171: 1.5571061 | H171: 89.215609 | I171: 16.764112 | J171: 0.51692163 | K171: 0.14058299 | L171: 0 | M171: 0 | N171: 0 | O171: 1.5468853 | P171: 88.63 | Q171: 16.778468 | U171: 0 | V171: 0 | W171: 0 | X171: 0
A172: 16.90764 | B172: 0.39780805 | C172: 0.25509962 | D172: -0.0019197101 | E172: 0.0089340059 | F172: 0.016729041 | G172: 1.5573384 | H172: 89.228919 | I172: 16.881089 | J172: 0.51736049 | K172: 0.15900085 | L172: 0 | M172: 0 | N172: 0 | O172: 1.548107 | P172: 88.7 | Q172: 16.897466 | R172: 0.54618054 | S172: 0.072291746 | T172: -0.010546543 | U172: 0.12670669 | V172: -0.026916483 | W172: 1.5522984 | X172: 88.940145
A173: 16.997623 | B173: 0.3978813 | C173: 0.26842958 | D173: -0.0010631121 | E173: 0.0098419489 | F173: 0.018018724 | G173: 1.5571087 | H173: 89.215758 | I173: 16.963026 | J173: 0.51763752 | K173: 0.17127979 | L173: 0 | M173: 0 | N173: 0 | O173: 1.547758 | P173: 88.68 | Q173: 16.971671 | R173: 0.54642692 | S173: 0.082258287 | T173: -0.012267787 | U173: 0.12521681 | V173: -0.027143752 | W173: 1.5519053 | X173: 88.917627
A174: 17.092604 | B174: 0.3976326 | C174: 0.28649163 | D174: 0.0032336586 | E174: 0.0105301 | F174: 0.017442433 | G174: 1.5567329 | H174: 89.194224 | I174: 17.043974 | J174: 0.51792188 | K174: 0.18364387 | L174: 0 | M174: 0 | N174: 0 | O174: 1.5479325 | P174: 88.69 | Q174: 17.074008 | R174: 0.54866894 | S174: 0.098672264 | T174: -0.015157239 | U174: 0.12339595 | V174: -0.027057302 | W174: 1.5532948 | X174: 88.997237
A175: 17.177588 | B175: 0.39800262 | C175: 0.30022889 | D175: 0.0026041456 | E175: 0.010997914 | F175: 0.018377403 | G175: 1.5571451 | H175: 89.217841 | I175: 17.183805 | J175: 0.51841976 | K175: 0.20555828 | L175: 0 | M175: 0 | N175: 0 | O175: 1.5479325 | P175: 88.69 | Q175: 17.192078 | R175: 0.55086346 | S175: 0.11946175 | T175: -0.018136429 | U175: 0.12162798 | V175: -0.027447589 | W175: 1.5543074 | X175: 89.055256
A176: 17.31758 | B176: 0.3981753 | C176: 0.32643875 | D176: 0.0073359315 | E176: 0.012535009 | F176: 0.01968693 | G176: 1.5559484 | H176: 89.149278 | I176: 17.300696 | J176: 0.51884576 | K176: 0.22440302 | L176: 0 | M176: 0 | N176: 0 | O176: 1.5486306 | P176: 88.73 | Q176: 17.292967 | R176: 0.55046979 | S176: 0.13321685 | T176: -0.018743244 | U176: 0.12082727 | V176: -0.028466278 | W176: 1.554738 | X176: 89.079924
...

Sheet Sheet2
A39: Reprojection Error | B39: 1
A40: solve method | B40: Iterative
A41: Detector | B41: SOFT
A42: iterationsCount | B42: 250
A43: confidence | B43: 0.999
A44: TERM_CRITERIA_COUNT | B44: 20

Sheet Sheet3
A1: T265 | C1: Camera | F1: T265 Offset: | G1: 0.11 | H1: 0.11
A2: Calibrated X | B2: Calibrated Y | C2: Calibrated X | D2: Calibrated Y | F2: Camera Offset: | G2: 0.087 | H2: 0.087
A3: =Sheet1!B4 +Sheet3!$G$1 -Sheet3!$G$1*COS(Sheet1!G4) -> -0.0014565635 | B3: =Sheet1!C4-Sheet3!$G$1*SIN(Sheet1!G4) -> 0.00077927559 | C3: =Sheet1!R8 - Sheet3!$G$2 + Sheet3!$G$2*COS(Sheet1!W8) -> 0.0043731934 | D3: =Sheet1!S8 + Sheet3!$G$2*SIN(Sheet1!W8) -> -0.0025207467
A4: =Sheet1!B5 +Sheet3!$G$1 -Sheet3!$G$1*COS(Sheet1!G5) -> -0.0012462215 | B4: =Sheet1!C5-Sheet3!$G$1*SIN(Sheet1!G5) -> 0.00065932759 | C4: =Sheet1!R9 - Sheet3!$G$2 + Sheet3!$G$2*COS(Sheet1!W9) -> 0.0042704252 | D4: =Sheet1!S9 + Sheet3!$G$2*SIN(Sheet1!W9) -> -0.0024060055
A5: =Sheet1!B6 +Sheet3!$G$1 -Sheet3!$G$1*COS(Sheet1!G6) -> 0.0001792522 | B5: =Sheet1!C6-Sheet3!$G$1*SIN(Sheet1!G6) -> 0.00024837467 | C5: =Sheet1!R10 - Sheet3!$G$2 + Sheet3!$G$2*COS(Sheet1!W10) -> 0.004353596 | D5: =Sheet1!S10 + Sheet3!$G$2*SIN(Sheet1!W10) -> -0.0024399088
A6: =Sheet1!B7 +Sheet3!$G$1 -Sheet3!$G$1*COS(Sheet1!G7) -> 0.00044791562 | B6: =Sheet1!C7-Sheet3!$G$1*SIN(Sheet1!G7) -> -0.00023026271 | C6: =Sheet1!R11 - Sheet3!$G$2 + Sheet3!$G$2*COS(Sheet1!W11) -> 0.0040834548 | D6: =Sheet1!S11 + Sheet3!$G$2*SIN(Sheet1!W11) -> -0.0025426986
A7: =Sheet1!B8 +Sheet3!$G$1 -Sheet3!$G$1*COS(Sheet1!G8) -> -0.00043558947 | B7: =Sheet1!C8-Sheet3!$G$1*SIN(Sheet1!G8) -> 0.00074523696 | C7: =Sheet1!R12 - Sheet3!$G$2 + Sheet3!$G$2*COS(Sheet1!W12) -> 0.0040111406 | D7: =Sheet1!S12 + Sheet3!$G$2*SIN(Sheet1!W12) -> -0.002587901
A8: =Sheet1!B9 +Sheet3!$G$1 -Sheet3!$G$1*COS(Sheet1!G9) -> -0.00048078357 | B8: =Sheet1!C9-Sheet3!$G$1*SIN(Sheet1!G9) -> 0.00039242363 | C8: =Sheet1!R13 - Sheet3!$G$2 + Sheet3!$G$2*COS(Sheet1!W13) -> 0.0036890894 | D8: =Sheet1!S13 + Sheet3!$G$2*SIN(Sheet1!W13) -> -0.0026333086
A9: =Sheet1!B10 +Sheet3!$G$1 -Sheet3!$G$1*COS(Sheet1!G10) -> -0.00053841654 | B9: =Sheet1!C10-Sheet3!$G$1*SIN(Sheet1!G10) -> 0.00056543618 | C9: =Sheet1!R14 - Sheet3!$G$2 + Sheet3!$G$2*COS(Sheet1!W14) -> 0.0037517246 | D9: =Sheet1!S14 + Sheet3!$G$2*SIN(Sheet1!W14) -> -0.0026452535
A10: =Sheet1!B11 +Sheet3!$G$1 -Sheet3!$G$1*COS(Sheet1!G11) -> 0.00029929358 | B10: =Sheet1!C11-Sheet3!$G$1*SIN(Sheet1!G11) -> 0.00019986624 | C10: =Sheet1!R15 - Sheet3!$G$2 + Sheet3!$G$2*COS(Sheet1!W15) -> 0.0036118543 | D10: =Sheet1!S15 + Sheet3!$G$2*SIN(Sheet1!W15) -> -0.0025653283
A11: =Sheet1!B12 +Sheet3!$G$1 -Sheet3!$G$1*COS(Sheet1!G12) -> -9.9969153e-05 | B11: =Sheet1!C12-Sheet3!$G$1*SIN(Sheet1!G12) -> 0.00011459584 | C11: =Sheet1!R16 - Sheet3!$G$2 + Sheet3!$G$2*COS(Sheet1!W16) -> 0.0037092223 | D11: =Sheet1!S16 + Sheet3!$G$2*SIN(Sheet1!W16) -> -0.0026061966
A12: =Sheet1!B13 +Sheet3!$G$1 -Sheet3!$G$1*COS(Sheet1!G13) -> -0.00066496535 | B12: =Sheet1!C13-Sheet3!$G$1*SIN(Sheet1!G13) -> 0.00049331758 | C12: =Sheet1!R17 - Sheet3!$G$2 + Sheet3!$G$2*COS(Sheet1!W17) -> 0.0036177357 | D12: =Sheet1!S17 + Sheet3!$G$2*SIN(Sheet1!W17) -> -0.0025519068
A13: =Sheet1!B14 +Sheet3!$G$1 -Sheet3!$G$1*COS(Sheet1!G14) -> -0.0003356106 | B13: =Sheet1!C14-Sheet3!$G$1*SIN(Sheet1!G14) -> 0.00029863617 | C13: =Sheet1!R18 - Sheet3!$G$2 + Sheet3!$G$2*COS(Sheet1!W18) -> 0.0037289154 | D13: =Sheet1!S18 + Sheet3!$G$2*SIN(Sheet1!W18) -> -0.0025076568
A14: =Sheet1!B15 +Sheet3!$G$1 -Sheet3!$G$1*COS(Sheet1!G15) -> -0.00037012024 | B14: =Sheet1!C15-Sheet3!$G$1*SIN(Sheet1!G15) -> 0.00039970253 | C14: =Sheet1!R19 - Sheet3!$G$2 + Sheet3!$G$2*COS(Sheet1!W19) -> 0.0037495152 | D14: =Sheet1!S19 + Sheet3!$G$2*SIN(Sheet1!W19) -> -0.0025960733
... A75: =Sheet1!B76 +Sheet3!$G$1 -Sheet3!$G$1*COS(Sheet1!G76) -> 0.43226982 | B75: =Sheet1!C76-Sheet3!$G$1*SIN(Sheet1!G76) -> -0.00050293686 | C75: =Sheet1!R80 - Sheet3!$G$2 + Sheet3!$G$2*COS(Sheet1!W80) -> 0.42864339 | D75: =Sheet1!S80 + Sheet3!$G$2*SIN(Sheet1!W80) -> 0.014536715
A76: =Sheet1!B77 +Sheet3!$G$1 -Sheet3!$G$1*COS(Sheet1!G77) -> 0.44700362 | B76: =Sheet1!C77-Sheet3!$G$1*SIN(Sheet1!G77) -> 0.00030586746
A77: =Sheet1!B78 +Sheet3!$G$1 -Sheet3!$G$1*COS(Sheet1!G78) -> 0.45923712 | B77: =Sheet1!C78-Sheet3!$G$1*SIN(Sheet1!G78) -> -0.00095731471 | C77: =Sheet1!R82 - Sheet3!$G$2 + Sheet3!$G$2*COS(Sheet1!W82) -> 0.4939788 | D77: =Sheet1!S82 + Sheet3!$G$2*SIN(Sheet1!W82) -> 0.0015552998
A78: =Sheet1!B79 +Sheet3!$G$1 -Sheet3!$G$1*COS(Sheet1!G79) -> 0.4813977 | B78: =Sheet1!C79-Sheet3!$G$1*SIN(Sheet1!G79) -> -0.00013715489 | C78: =Sheet1!R83 - Sheet3!$G$2 + Sheet3!$G$2*COS(Sheet1!W83) -> 0.4939788 | D78: =Sheet1!S83 + Sheet3!$G$2*SIN(Sheet1!W83) -> 0.0015552998
A79: =Sheet1!B80 +Sheet3!$G$1 -Sheet3!$G$1*COS(Sheet1!G80) -> 0.49651514 | B79: =Sheet1!C80-Sheet3!$G$1*SIN(Sheet1!G80) -> -0.00022836884 | C79: =Sheet1!R84 - Sheet3!$G$2 + Sheet3!$G$2*COS(Sheet1!W84) -> 0.48008015 | D79: =Sheet1!S84 + Sheet3!$G$2*SIN(Sheet1!W84) -> 0.0031561332
A80: =Sheet1!B81 +Sheet3!$G$1 -Sheet3!$G$1*COS(Sheet1!G81) -> 0.51168996 | B80: =Sheet1!C81-Sheet3!$G$1*SIN(Sheet1!G81) -> -0.0005900474 | C80: =Sheet1!R85 - Sheet3!$G$2 + Sheet3!$G$2*COS(Sheet1!W85) -> 0.48356517 | D80: =Sheet1!S85 + Sheet3!$G$2*SIN(Sheet1!W85) -> 0.0036480373
A81: =Sheet1!B82 +Sheet3!$G$1 -Sheet3!$G$1*COS(Sheet1!G82) -> 0.51549241 | B81: =Sheet1!C82-Sheet3!$G$1*SIN(Sheet1!G82) -> 0.00053918891 | C81: =Sheet1!R86 - Sheet3!$G$2 + Sheet3!$G$2*COS(Sheet1!W86) -> 0.48673257 | D81: =Sheet1!S86 + Sheet3!$G$2*SIN(Sheet1!W86) -> 0.0023599604
A82: =Sheet1!B83 +Sheet3!$G$1 -Sheet3!$G$1*COS(Sheet1!G83) -> 0.50403215 | B82: =Sheet1!C83-Sheet3!$G$1*SIN(Sheet1!G83) -> -0.0001813077 | C82: =Sheet1!R87 - Sheet3!$G$2 + Sheet3!$G$2*COS(Sheet1!W87) -> 0.48162447 | D82: =Sheet1!S87 + Sheet3!$G$2*SIN(Sheet1!W87) -> 0.0047079046
A83: =Sheet1!B84 +Sheet3!$G$1 -Sheet3!$G$1*COS(Sheet1!G84) -> 0.50546045 | B83: =Sheet1!C84-Sheet3!$G$1*SIN(Sheet1!G84) -> 0.000429649 | C83: =Sheet1!R88 - Sheet3!$G$2 + Sheet3!$G$2*COS(Sheet1!W88) -> 0.48787575 | D83: =Sheet1!S88 + Sheet3!$G$2*SIN(Sheet1!W88) -> 0.0024337242
A84: =Sheet1!B85 +Sheet3!$G$1 -Sheet3!$G$1*COS(Sheet1!G85) -> 0.50694644 | B84: =Sheet1!C85-Sheet3!$G$1*SIN(Sheet1!G85) -> 0.00015112158 | C84: =Sheet1!R89 - Sheet3!$G$2 + Sheet3!$G$2*COS(Sheet1!W89) -> 0.48338231 | D84: =Sheet1!S89 + Sheet3!$G$2*SIN(Sheet1!W89) -> 0.0046295896
A85: =Sheet1!B86 +Sheet3!$G$1 -Sheet3!$G$1*COS(Sheet1!G86) -> 0.50568466 | B85: =Sheet1!C86-Sheet3!$G$1*SIN(Sheet1!G86) -> 0.00012134593 | C85: =Sheet1!R90 - Sheet3!$G$2 + Sheet3!$G$2*COS(Sheet1!W90) -> 0.48549133 | D85: =Sheet1!S90 + Sheet3!$G$2*SIN(Sheet1!W90) -> 0.0038427913
A86: =Sheet1!B87 +Sheet3!$G$1 -Sheet3!$G$1*COS(Sheet1!G87) -> 0.50587313 | B86: =Sheet1!C87-Sheet3!$G$1*SIN(Sheet1!G87) -> -0.00043635235 | C86: =Sheet1!R91 - Sheet3!$G$2 + Sheet3!$G$2*COS(Sheet1!W91) -> 0.48518469 | D86: =Sheet1!S91 + Sheet3!$G$2*SIN(Sheet1!W91) -> 0.0039687618
A87: =Sheet1!B88 +Sheet3!$G$1 -Sheet3!$G$1*COS(Sheet1!G88) -> 0.50563988 | B87: =Sheet1!C88-Sheet3!$G$1*SIN(Sheet1!G88) -> -0.00015801983 | C87: =Sheet1!R92 - Sheet3!$G$2 + Sheet3!$G$2*COS(Sheet1!W92) -> 0.4853835 | D87: =Sheet1!S92 + Sheet3!$G$2*SIN(Sheet1!W92) -> 0.0037230186
A88: =Sheet1!B89 +Sheet3!$G$1 -Sheet3!$G$1*COS(Sheet1!G89) -> 0.50521903 | B88: =Sheet1!C89-Sheet3!$G$1*SIN(Sheet1!G89) -> 0.00022991946 | C88: =Sheet1!R93 - Sheet3!$G$2 + Sheet3!$G$2*COS(Sheet1!W93) -> 0.48086037 | D88: =Sheet1!S93 + Sheet3!$G$2*SIN(Sheet1!W93) -> 0.0070749345
... A165: =Sheet1!B166 +Sheet3!$G$1 -Sheet3!$G$1*COS(Sheet1!G166) -> 0.5054317 | B165: =Sheet1!C166-Sheet3!$G$1*SIN(Sheet1!G166) -> 0.044716252 | C165: =Sheet1!R170 - Sheet3!$G$2 + Sheet3!$G$2*COS(Sheet1!W170) -> 0.45910768 | D165: =Sheet1!S170 + Sheet3!$G$2*SIN(Sheet1!W170) -> 0.11539089
A166: =Sheet1!B167 +Sheet3!$G$1 -Sheet3!$G$1*COS(Sheet1!G167) -> 0.50563731 | B166: =Sheet1!C167-Sheet3!$G$1*SIN(Sheet1!G167) -> 0.059342192
A167: =Sheet1!B168 +Sheet3!$G$1 -Sheet3!$G$1*COS(Sheet1!G168) -> 0.50539354 | B167: =Sheet1!C168-Sheet3!$G$1*SIN(Sheet1!G168) -> 0.079015194 | C167: =Sheet1!R172 - Sheet3!$G$2 + Sheet3!$G$2*COS(Sheet1!W172) -> 0.46078977 | D167: =Sheet1!S172 + Sheet3!$G$2*SIN(Sheet1!W172) -> 0.15927686
A168: =Sheet1!B169 +Sheet3!$G$1 -Sheet3!$G$1*COS(Sheet1!G169) -> 0.50589955 | B168: =Sheet1!C169-Sheet3!$G$1*SIN(Sheet1!G169) -> 0.095250236 | C168: =Sheet1!R173 - Sheet3!$G$2 + Sheet3!$G$2*COS(Sheet1!W173) -> 0.46107034 | D168: =Sheet1!S173 + Sheet3!$G$2*SIN(Sheet1!W173) -> 0.16924276
A169: =Sheet1!B170 +Sheet3!$G$1 -Sheet3!$G$1*COS(Sheet1!G170) -> 0.50657253 | B169: =Sheet1!C170-Sheet3!$G$1*SIN(Sheet1!G170) -> 0.1095333 | C169: =Sheet1!R174 - Sheet3!$G$2 + Sheet3!$G$2*COS(Sheet1!W174) -> 0.46319149 | D169: =Sheet1!S174 + Sheet3!$G$2*SIN(Sheet1!W174) -> 0.18565894
A170: =Sheet1!B171 +Sheet3!$G$1 -Sheet3!$G$1*COS(Sheet1!G171) -> 0.50646674 | B170: =Sheet1!C171-Sheet3!$G$1*SIN(Sheet1!G171) -> 0.12267319 | C170: =Sheet1!R175 - Sheet3!$G$2 + Sheet3!$G$2*COS(Sheet1!W175) -> 0.46529793 | D170: =Sheet1!S175 + Sheet3!$G$2*SIN(Sheet1!W175) -> 0.20644993
A171: =Sheet1!B172 +Sheet3!$G$1 -Sheet3!$G$1*COS(Sheet1!G172) -> 0.50632772 | B171: =Sheet1!C172-Sheet3!$G$1*SIN(Sheet1!G172) -> 0.14510959 | C171: =Sheet1!R176 - Sheet3!$G$2 + Sheet3!$G$2*COS(Sheet1!W176) -> 0.4648668 | D171: =Sheet1!S176 + Sheet3!$G$2*SIN(Sheet1!W176) -> 0.22020564
A172: =Sheet1!B173 +Sheet3!$G$1 -Sheet3!$G$1*COS(Sheet1!G173) -> 0.50637571 | B172: =Sheet1!C173-Sheet3!$G$1*SIN(Sheet1!G173) -> 0.15843988 | C172: =Sheet1!R177 - Sheet3!$G$2 + Sheet3!$G$2*COS(Sheet1!W177) -> 0.4665305 | D172: =Sheet1!S177 + Sheet3!$G$2*SIN(Sheet1!W177) -> 0.23659005
A173: =Sheet1!B174 +Sheet3!$G$1 -Sheet3!$G$1*COS(Sheet1!G174) -> 0.50608567 | B173: =Sheet1!C174-Sheet3!$G$1*SIN(Sheet1!G174) -> 0.17650251 | C173: =Sheet1!R178 - Sheet3!$G$2 + Sheet3!$G$2*COS(Sheet1!W178) -> 0.4666411 | D173: =Sheet1!S178 + Sheet3!$G$2*SIN(Sheet1!W178) -> 0.2462185
A174: =Sheet1!B175 +Sheet3!$G$1 -Sheet3!$G$1*COS(Sheet1!G175) -> 0.50650103 | B174: =Sheet1!C175-Sheet3!$G$1*SIN(Sheet1!G175) -> 0.19023914 | C174: =Sheet1!R179 - Sheet3!$G$2 + Sheet3!$G$2*COS(Sheet1!W179) -> 0.46587696 | D174: =Sheet1!S179 + Sheet3!$G$2*SIN(Sheet1!W179) -> 0.25611243
A175: =Sheet1!B176 +Sheet3!$G$1 -Sheet3!$G$1*COS(Sheet1!G176) -> 0.50654209 | B175: =Sheet1!C176-Sheet3!$G$1*SIN(Sheet1!G176) -> 0.21645088 | C175: =Sheet1!R180 - Sheet3!$G$2 + Sheet3!$G$2*COS(Sheet1!W180) -> 0.46560317 | D175: =Sheet1!S180 + Sheet3!$G$2*SIN(Sheet1!W180) -> 0.26016902
A176: =Sheet1!B177 +Sheet3!$G$1 -Sheet3!$G$1*COS(Sheet1!G177) -> 0.50719204 | B176: =Sheet1!C177-Sheet3!$G$1*SIN(Sheet1!G177) -> 0.23266309 | C176: =Sheet1!R181 - Sheet3!$G$2 + Sheet3!$G$2*COS(Sheet1!W181) -> 0.46738403 | D176: =Sheet1!S181 + Sheet3!$G$2*SIN(Sheet1!W181) -> 0.2990052
...
